Workbook
Name Slicer_clinic_id: #N/A
Name Slicer_payer_name: #N/A

Sheet Dashboard
A1: Payer Underpayment Analysis
A3: Paid claims | B3: =COUNTIF(Claims!M:M,"Paid") -> 4321
A4: Expected payment | B4: =SUMIFS(Claims!S:S,Claims!M:M,"Paid") -> 2968252.8
A5: Allowed amount | B5: =SUMIFS(Claims!J:J,Claims!M:M,"Paid") -> 2966855.9
A6: underpaid claims | B6: =COUNTIF(Claims!U:U,"Underpaid") -> 1459
A7: underpaid $ | B7: =SUMIFS(Claims!T:T,Claims!U:U,"Underpaid") -> 107894.87
A8: Underpaid rate | B8: =B6/B3 -> 0.33765332
A9: Avg underpayment/claim | B9: =B7/B6 -> 73.951247
A10: Revenue Leakage | B10: =B7/B4 -> 0.036349623
A11: Top underpaying payer | B11: =Pivot_Payer!A4 -> Summit Health Commercial

Sheet Payers
A1: payer_id | B1: payer_name | C1: payer_type | D1: avg_contract_days_to_pay
A2: P01 | B2: Blue Horizon Commercial | C2: Commercial | D2: 28
A3: P02 | B3: Summit Health Commercial | C3: Commercial | D3: 32
A4: P03 | B4: Keystone Commercial PPO | C4: Commercial | D4: 45
A5: P04 | B5: Medicare Part B | C5: Medicare | D5: 18
A6: P05 | B6: Sunshine Medicare Advantage | C6: Medicare Advantage | D6: 52
A7: P06 | B7: Florida Medicaid | C7: Medicaid | D7: 40
A8: P07 | B8: Coastal Medicaid MCO | C8: Medicaid Managed Care | D8: 61
A9: P08 | B9: Self-Pay | C9: Self-Pay | D9: 75

Sheet Contract
A1: payer_id | B1: contract_rate
A2: P01 | B2: 0.45
A3: P02 | B3: 0.43
A4: P03 | B4: 0.47
A5: P04 | B5: 0.36
A6: P05 | B6: 0.38
A7: P06 | B7: 0.27
A8: P07 | B8: 0.28
A9: P08 | B9: 1

Sheet CPT
A1: cpt_code | B1: description | C1: service_category | D1: standard_charge
A2: 99213 | B2: Office visit, established, low | C2: E/M | D2: 145
A3: 99214 | B3: Office visit, established, moderate | C3: E/M | D3: 210
A4: 99204 | B4: Office visit, new, moderate | C4: E/M | D4: 260
A5: 97110 | B5: Therapeutic exercise, 15 min | C5: Therapy | D5: 62
A6: 97140 | B6: Manual therapy, 15 min | C6: Therapy | D6: 58
A7: 72148 | B7: MRI lumbar spine w/o contrast | C7: Imaging | D7: 1150
A8: 73721 | B8: MRI knee w/o contrast | C8: Imaging | D8: 1050
A9: 20610 | B9: Joint injection, major joint | C9: Procedure | D9: 240
A10: J0702 | B10: Betamethasone injection, 3 mg | C10: Drug | D10: 38
A11: J1745 | B11: Infliximab injection, 10 mg | C11: Specialty Drug | D11: 1450
A12: 96413 | B12: Chemo/infusion admin, first hour | C12: Infusion | D12: 420
A13: 29881 | B13: Knee arthroscopy w/ meniscectomy | C13: Surgery | D13: 4800

Sheet Pivot_Payer
A1: underpaid_flag | B1: Underpaid
A3: Row Labels | B3: Count of claim_id | C3: Sum of variance
A4: Summit Health Commercial | B4: 315 | C4: 33646.42
A5: Blue Horizon Commercial | B5: 376 | C5: 29896.08
A6: Medicare Part B | B6: 259 | C6: 14184.74
A7: Keystone Commercial PPO | B7: 134 | C7: 11666.13
A8: Sunshine Medicare Advantage | B8: 152 | C8: 10661.95
A9: Florida Medicaid | B9: 115 | C9: 4975.75
A10: Coastal Medicaid MCO | B10: 108 | C10: 2863.8
A11: Grand Total | B11: 1459 | C11: 107894.87

Sheet Pivot_CPT
A1: underpaid_flag | B1: Underpaid
A3: Row Labels | B3: Count of claim_id | C3: Sum of variance
A4: J1745 | B4: 80 | C4: 80360.04
A5: 29881 | B5: 66 | C5: 12568.72
A6: 72148 | B6: 68 | C6: 3310.94
A7: 73721 | B7: 68 | C7: 2750.84
A8: 99214 | B8: 288 | C8: 2628.25
A9: 99204 | B9: 179 | C9: 1896.08
A10: 96413 | B10: 75 | C10: 1396.71
A11: 99213 | B11: 179 | C11: 1048.29
A12: 20610 | B12: 69 | C12: 661.43
A13: 97110 | B13: 91 | C13: 517.97
A14: 97140 | B14: 86 | C14: 424.72
A15: J0702 | B15: 210 | C15: 330.88
A16: Grand Total | B16: 1459 | C16: 107894.87

Sheet Pivot_month
A1: underpaid_flag | B1: Underpaid
A3: Row Labels | B3: Count of claim_id | C3: Sum of variance
A4: 2025-10 | B4: 135 | C4: 10659.51
A5: 2025-11 | B5: 133 | C5: 4071.76
A6: 2025-12 | B6: 137 | C6: 11882.73
A7: 2026-01 | B7: 117 | C7: 6135.12
A8: 2026-02 | B8: 141 | C8: 11018.49
A9: 2026-03 | B9: 127 | C9: 4128.73
A10: 2026-04 | B10: 153 | C10: 13326.04
A11: 2026-05 | B11: 150 | C11: 13628.07
A12: 2026-06 | B12: 136 | C12: 16236.24
A13: 2026-07 | B13: 125 | C13: 8490.67
A14: 2026-08 | B14: 92 | C14: 7903.16
A15: 2026-09 | B15: 13 | C15: 414.35
A16: Grand Total | B16: 1459 | C16: 107894.87

Sheet Claims
A1: claim_id | B1: patient_id | C1: payer_id | D1: clinic_id | E1: cpt_code | F1: units | G1: service_date | H1: submit_date | I1: billed_amount | J1: allowed_amount | K1: paid_amount | L1: patient_responsibility | M1: claim_status | N1: denial_carc | O1: adjudication_date | P1: paid_date | Q1: std_charge | R1: contract_rate | S1: expected_payment | T1: variance | U1: underpaid_flag | V1: payer_name | W1: service_month
A2: CLM100001 | B2: PT10383 | C2: P05 | D2: C02 | E2: 99213 | F2: 1 | G2: 46056 | H2: 46062 | I2: 142.59 | J2: 61.2 | K2: 61.2 | L2: 0 | M2: Paid | O2: 46127 | P2: 46127 | Q2: =_xlfn.XLOOKUP(E2,CPT!$A$2:$A$13,CPT!$D$2:$D$13) -> 145 | R2: =_xlfn.XLOOKUP(C2,Contract!$A$2:$A$9,Contract!$B$2:$B$9) -> 0.38 | S2: =ROUND(Q2*F2*R2,2) -> 55.1 | T2: =IF(M2="Paid",S2-J2,"") -> -6.1 | U2: =IF(M2<>"Paid","",IF(T2>S2*0.05,"Underpaid","OK")) -> OK | V2: =_xlfn.XLOOKUP(C2,Payers!$A$2:$A$9,Payers!$B$2:$B$9) -> Sunshine Medicare Advantage | W2: =TEXT(G2,"yyyy-mm") -> 2026-02
A3: CLM100002 | B3: PT13315 | C3: P04 | D3: C01 | E3: 20610 | F3: 1 | G3: 46218 | H3: 46223 | I3: 235.66 | J3: 77.46 | K3: 69.71 | L3: 7.75 | M3: Paid | O3: 46243 | P3: 46243 | Q3: =_xlfn.XLOOKUP(E3,CPT!$A$2:$A$13,CPT!$D$2:$D$13) -> 240 | R3: =_xlfn.XLOOKUP(C3,Contract!$A$2:$A$9,Contract!$B$2:$B$9) -> 0.36 | S3: =ROUND(Q3*F3*R3,2) -> 86.4 | T3: =IF(M3="Paid",S3-J3,"") -> 8.94 | U3: =IF(M3<>"Paid","",IF(T3>S3*0.05,"Underpaid","OK")) -> Underpaid | V3: =_xlfn.XLOOKUP(C3,Payers!$A$2:$A$9,Payers!$B$2:$B$9) -> Medicare Part B | W3: =TEXT(G3,"yyyy-mm") -> 2026-07
A4: CLM100003 | B4: PT12988 | C4: P05 | D4: C04 | E4: 97110 | F4: 1 | G4: 46105 | H4: 46118 | I4: 60.72 | M4: Denied | N4: CO-16 | O4: 46147 | Q4: =_xlfn.XLOOKUP(E4,CPT!$A$2:$A$13,CPT!$D$2:$D$13) -> 62 | R4: =_xlfn.XLOOKUP(C4,Contract!$A$2:$A$9,Contract!$B$2:$B$9) -> 0.38 | S4: =ROUND(Q4*F4*R4,2) -> 23.56 | T4: =IF(M4="Paid",S4-J4,"") | U4: =IF(M4<>"Paid","",IF(T4>S4*0.05,"Underpaid","OK")) | V4: =_xlfn.XLOOKUP(C4,Payers!$A$2:$A$9,Payers!$B$2:$B$9) -> Sunshine Medicare Advantage | W4: =TEXT(G4,"yyyy-mm") -> 2026-03
A5: CLM100005 | B5: PT12745 | C5: P06 | D5: C03 | E5: J1745 | F5: 30 | G5: 45982 | H5: 45987 | I5: 42920.51 | J5: 11120.5 | K5: 11120.5 | L5: 0 | M5: Paid | O5: 46013 | P5: 46013 | Q5: =_xlfn.XLOOKUP(E5,CPT!$A$2:$A$13,CPT!$D$2:$D$13) -> 1450 | R5: =_xlfn.XLOOKUP(C5,Contract!$A$2:$A$9,Contract!$B$2:$B$9) -> 0.27 | S5: =ROUND(Q5*F5*R5,2) -> 11745 | T5: =IF(M5="Paid",S5-J5,"") -> 624.5 | U5: =IF(M5<>"Paid","",IF(T5>S5*0.05,"Underpaid","OK")) -> Underpaid | V5: =_xlfn.XLOOKUP(C5,Payers!$A$2:$A$9,Payers!$B$2:$B$9) -> Florida Medicaid | W5: =TEXT(G5,"yyyy-mm") -> 2025-11
A6: CLM100006 | B6: PT12804 | C6: P04 | D6: C01 | E6: J0702 | F6: 1 | G6: 46242 | H6: 46246 | I6: 38.31 | J6: 13.63 | K6: 13.63 | L6: 0 | M6: Paid | O6: 46262 | P6: 46262 | Q6: =_xlfn.XLOOKUP(E6,CPT!$A$2:$A$13,CPT!$D$2:$D$13) -> 38 | R6: =_xlfn.XLOOKUP(C6,Contract!$A$2:$A$9,Contract!$B$2:$B$9) -> 0.36 | S6: =ROUND(Q6*F6*R6,2) -> 13.68 | T6: =IF(M6="Paid",S6-J6,"") -> 0.05 | U6: =IF(M6<>"Paid","",IF(T6>S6*0.05,"Underpaid","OK")) -> OK | V6: =_xlfn.XLOOKUP(C6,Payers!$A$2:$A$9,Payers!$B$2:$B$9) -> Medicare Part B | W6: =TEXT(G6,"yyyy-mm") -> 2026-08
A7: CLM100007 | B7: PT10870 | C7: P05 | D7: C01 | E7: 29881 | F7: 1 | G7: 46048 | H7: 46055 | I7: 4892.68 | J7: 1618.87 | K7: 1456.98 | L7: 161.89 | M7: Paid | O7: 46142 | P7: 46142 | Q7: =_xlfn.XLOOKUP(E7,CPT!$A$2:$A$13,CPT!$D$2:$D$13) -> 4800 | R7: =_xlfn.XLOOKUP(C7,Contract!$A$2:$A$9,Contract!$B$2:$B$9) -> 0.38 | S7: =ROUND(Q7*F7*R7,2) -> 1824 | T7: =IF(M7="Paid",S7-J7,"") -> 205.13 | U7: =IF(M7<>"Paid","",IF(T7>S7*0.05,"Underpaid","OK")) -> Underpaid | V7: =_xlfn.XLOOKUP(C7,Payers!$A$2:$A$9,Payers!$B$2:$B$9) -> Sunshine Medicare Advantage | W7: =TEXT(G7,"yyyy-mm") -> 2026-01
A8: CLM100008 | B8: PT11635 | C8: P07 | D8: C03 | E8: 96413 | F8: 1 | G8: 46260 | H8: 46262 | I8: 418.96 | M8: Denied | N8: CO-50 | O8: 46289 | Q8: =_xlfn.XLOOKUP(E8,CPT!$A$2:$A$13,CPT!$D$2:$D$13) -> 420 | R8: =_xlfn.XLOOKUP(C8,Contract!$A$2:$A$9,Contract!$B$2:$B$9) -> 0.28 | S8: =ROUND(Q8*F8*R8,2) -> 117.6 | T8: =IF(M8="Paid",S8-J8,"") | U8: =IF(M8<>"Paid","",IF(T8>S8*0.05,"Underpaid","OK")) | V8: =_xlfn.XLOOKUP(C8,Payers!$A$2:$A$9,Payers!$B$2:$B$9) -> Coastal Medicaid MCO | W8: =TEXT(G8,"yyyy-mm") -> 2026-08
A9: CLM100009 | B9: PT11563 | C9: P03 | D9: C04 | E9: 97110 | F9: 1 | G9: 45977 | H9: 45978 | I9: 63.34 | J9: 30.83 | K9: 24.66 | L9: 6.17 | M9: Paid | O9: 46008 | P9: 46008 | Q9: =_xlfn.XLOOKUP(E9,CPT!$A$2:$A$13,CPT!$D$2:$D$13) -> 62 | R9: =_xlfn.XLOOKUP(C9,Contract!$A$2:$A$9,Contract!$B$2:$B$9) -> 0.47 | S9: =ROUND(Q9*F9*R9,2) -> 29.14 | T9: =IF(M9="Paid",S9-J9,"") -> -1.69 | U9: =IF(M9<>"Paid","",IF(T9>S9*0.05,"Underpaid","OK")) -> OK | V9: =_xlfn.XLOOKUP(C9,Payers!$A$2:$A$9,Payers!$B$2:$B$9) -> Keystone Commercial PPO | W9: =TEXT(G9,"yyyy-mm") -> 2025-11
A10: CLM100010 | B10: PT10456 | C10: P04 | D10: C02 | E10: J0702 | F10: 1 | G10: 46214 | H10: 46215 | I10: 38.82 | J10: 14.77 | K10: 13.29 | L10: 1.48 | M10: Paid | O10: 46228 | P10: 46228 | Q10: =_xlfn.XLOOKUP(E10,CPT!$A$2:$A$13,CPT!$D$2:$D$13) -> 38 | R10: =_xlfn.XLOOKUP(C10,Contract!$A$2:$A$9,Contract!$B$2:$B$9) -> 0.36 | S10: =ROUND(Q10*F10*R10,2) -> 13.68 | T10: =IF(M10="Paid",S10-J10,"") -> -1.09 | U10: =IF(M10<>"Paid","",IF(T10>S10*0.05,"Underpaid","OK")) -> OK | V10: =_xlfn.XLOOKUP(C10,Payers!$A$2:$A$9,Payers!$B$2:$B$9) -> Medicare Part B | W10: =TEXT(G10,"yyyy-mm") -> 2026-07
A11: CLM100011 | B11: PT13447 | C11: P03 | D11: C01 | E11: 99214 | F11: 1 | G11: 46065 | H11: 46071 | I11: 215.95 | J11: 89.54 | K11: 80.59 | L11: 8.95 | M11: Paid | O11: 46113 | P11: 46113 | Q11: =_xlfn.XLOOKUP(E11,CPT!$A$2:$A$13,CPT!$D$2:$D$13) -> 210 | R11: =_xlfn.XLOOKUP(C11,Contract!$A$2:$A$9,Contract!$B$2:$B$9) -> 0.47 | S11: =ROUND(Q11*F11*R11,2) -> 98.7 | T11: =IF(M11="Paid",S11-J11,"") -> 9.16 | U11: =IF(M11<>"Paid","",IF(T11>S11*0.05,"Underpaid","OK")) -> Underpaid | V11: =_xlfn.XLOOKUP(C11,Payers!$A$2:$A$9,Payers!$B$2:$B$9) -> Keystone Commercial PPO | W11: =TEXT(G11,"yyyy-mm") -> 2026-02
A12: CLM100012 | B12: PT13406 | C12: P01 | D12: C02 | E12: 99214 | F12: 1 | G12: 46013 | H12: 46020 | I12: 210.5 | J12: 80.01 | K12: 72.01 | L12: 8 | M12: Paid | O12: 46047 | P12: 46047 | Q12: =_xlfn.XLOOKUP(E12,CPT!$A$2:$A$13,CPT!$D$2:$D$13) -> 210 | R12: =_xlfn.XLOOKUP(C12,Contract!$A$2:$A$9,Contract!$B$2:$B$9) -> 0.45 | S12: =ROUND(Q12*F12*R12,2) -> 94.5 | T12: =IF(M12="Paid",S12-J12,"") -> 14.49 | U12: =IF(M12<>"Paid","",IF(T12>S12*0.05,"Underpaid","OK")) -> Underpaid | V12: =_xlfn.XLOOKUP(C12,Payers!$A$2:$A$9,Payers!$B$2:$B$9) -> Blue Horizon Commercial | W12: =TEXT(G12,"yyyy-mm") -> 2025-12
A13: CLM100014 | B13: PT12920 | C13: P04 | D13: C03 | E13: J1745 | F13: 10 | G13: 46212 | H13: 46221 | I13: 14295.6 | J13: 4684.97 | K13: 4684.97 | L13: 0 | M13: Paid | O13: 46239 | P13: 46239 | Q13: =_xlfn.XLOOKUP(E13,CPT!$A$2:$A$13,CPT!$D$2:$D$13) -> 1450 | R13: =_xlfn.XLOOKUP(C13,Contract!$A$2:$A$9,Contract!$B$2:$B$9) -> 0.36 | S13: =ROUND(Q13*F13*R13,2) -> 5220 | T13: =IF(M13="Paid",S13-J13,"") -> 535.03 | U13: =IF(M13<>"Paid","",IF(T13>S13*0.05,"Underpaid","OK")) -> Underpaid | V13: =_xlfn.XLOOKUP(C13,Payers!$A$2:$A$9,Payers!$B$2:$B$9) -> Medicare Part B | W13: =TEXT(G13,"yyyy-mm") -> 2026-07
A14: CLM100015 | B14: PT10029 | C14: P04 | D14: C01 | E14: J0702 | F14: 1 | G14: 46155 | H14: 46158 | I14: 38.91 | J14: 12.11 | K14: 12.11 | L14: 0 | M14: Paid | O14: 46182 | P14: 46182 | Q14: =_xlfn.XLOOKUP(E14,CPT!$A$2:$A$13,CPT!$D$2:$D$13) -> 38 | R14: =_xlfn.XLOOKUP(C14,Contract!$A$2:$A$9,Contract!$B$2:$B$9) -> 0.36 | S14: =ROUND(Q14*F14*R14,2) -> 13.68 | T14: =IF(M14="Paid",S14-J14,"") -> 1.57 | U14: =IF(M14<>"Paid","",IF(T14>S14*0.05,"Underpaid","OK")) -> Underpaid | V14: =_xlfn.XLOOKUP(C14,Payers!$A$2:$A$9,Payers!$B$2:$B$9) -> Medicare Part B | W14: =TEXT(G14,"yyyy-mm") -> 2026-05
A15: CLM100016 | B15: PT10877 | C15: P01 | D15: C01 | E15: J0702 | F15: 1 | G15: 45965 | H15: 45973 | I15: 38.92 | M15: Denied | N15: CO-16 | O15: 46002 | Q15: =_xlfn.XLOOKUP(E15,CPT!$A$2:$A$13,CPT!$D$2:$D$13) -> 38 | R15: =_xlfn.XLOOKUP(C15,Contract!$A$2:$A$9,Contract!$B$2:$B$9) -> 0.45 | S15: =ROUND(Q15*F15*R15,2) -> 17.1 | T15: =IF(M15="Paid",S15-J15,"") | U15: =IF(M15<>"Paid","",IF(T15>S15*0.05,"Underpaid","OK")) | V15: =_xlfn.XLOOKUP(C15,Payers!$A$2:$A$9,Payers!$B$2:$B$9) -> Blue Horizon Commercial | W15: =TEXT(G15,"yyyy-mm") -> 2025-11
A16: CLM100017 | B16: PT13279 | C16: P01 | D16: C04 | E16: 97110 | F16: 2 | G16: 46268 | H16: 46271 | I16: 122.92 | M16: Pending | Q16: =_xlfn.XLOOKUP(E16,CPT!$A$2:$A$13,CPT!$D$2:$D$13) -> 62 | R16: =_xlfn.XLOOKUP(C16,Contract!$A$2:$A$9,Contract!$B$2:$B$9) -> 0.45 | S16: =ROUND(Q16*F16*R16,2) -> 55.8 | T16: =IF(M16="Paid",S16-J16,"") | U16: =IF(M16<>"Paid","",IF(T16>S16*0.05,"Underpaid","OK")) | V16: =_xlfn.XLOOKUP(C16,Payers!$A$2:$A$9,Payers!$B$2:$B$9) -> Blue Horizon Commercial | W16: =TEXT(G16,"yyyy-mm") -> 2026-09
A17: CLM100018 | B17: PT10207 | C17: P01 | D17: C04 | E17: 97110 | F17: 2 | G17: 46205 | H17: 46206 | I17: 121.32 | J17: 47.38 | K17: 47.38 | L17: 0 | M17: Paid | O17: 46239 | P17: 46239 | Q17: =_xlfn.XLOOKUP(E17,CPT!$A$2:$A$13,CPT!$D$2:$D$13) -> 62 | R17: =_xlfn.XLOOKUP(C17,Contract!$A$2:$A$9,Contract!$B$2:$B$9) -> 0.45 | S17: =ROUND(Q17*F17*R17,2) -> 55.8 | T17: =IF(M17="Paid",S17-J17,"") -> 8.42 | U17: =IF(M17<>"Paid","",IF(T17>S17*0.05,"Underpaid","OK")) -> Underpaid | V17: =_xlfn.XLOOKUP(C17,Payers!$A$2:$A$9,Payers!$B$2:$B$9) -> Blue Horizon Commercial | W17: =TEXT(G17,"yyyy-mm") -> 2026-07
A18: CLM100019 | B18: PT10674 | C18: P06 | D18: C03 | E18: 99214 | F18: 1 | G18: 45978 | H18: 45986 | I18: 215.37 | J18: 57.89 | K18: 57.89 | L18: 0 | M18: Paid | O18: 46028 | P18: 46028 | Q18: =_xlfn.XLOOKUP(E18,CPT!$A$2:$A$13,CPT!$D$2:$D$13) -> 210 | R18: =_xlfn.XLOOKUP(C18,Contract!$A$2:$A$9,Contract!$B$2:$B$9) -> 0.27 | S18: =ROUND(Q18*F18*R18,2) -> 56.7 | T18: =IF(M18="Paid",S18-J18,"") -> -1.19 | U18: =IF(M18<>"Paid","",IF(T18>S18*0.05,"Underpaid","OK")) -> OK | V18: =_xlfn.XLOOKUP(C18,Payers!$A$2:$A$9,Payers!$B$2:$B$9) -> Florida Medicaid | W18: =TEXT(G18,"yyyy-mm") -> 2025-11
A19: CLM100020 | B19: PT10634 | C19: P02 | D19: C02 | E19: J0702 | F19: 1 | G19: 46163 | H19: 46168 | I19: 37.51 | J19: 17.45 | K19: 13.96 | L19: 3.49 | M19: Paid | O19: 46209 | P19: 46209 | Q19: =_xlfn.XLOOKUP(E19,CPT!$A$2:$A$13,CPT!$D$2:$D$13) -> 38 | R19: =_xlfn.XLOOKUP(C19,Contract!$A$2:$A$9,Contract!$B$2:$B$9) -> 0.43 | S19: =ROUND(Q19*F19*R19,2) -> 16.34 | T19: =IF(M19="Paid",S19-J19,"") -> -1.11 | U19: =IF(M19<>"Paid","",IF(T19>S19*0.05,"Underpaid","OK")) -> OK | V19: =_xlfn.XLOOKUP(C19,Payers!$A$2:$A$9,Payers!$B$2:$B$9) -> Summit Health Commercial | W19: =TEXT(G19,"yyyy-mm") -> 2026-05
A20: CLM100021 | B20: PT13492 | C20: P08 | D20: C01 | E20: 99214 | F20: 1 | G20: 46227 | H20: 46228 | I20: 212.97 | M20: Pending | Q20: =_xlfn.XLOOKUP(E20,CPT!$A$2:$A$13,CPT!$D$2:$D$13) -> 210 | R20: =_xlfn.XLOOKUP(C20,Contract!$A$2:$A$9,Contract!$B$2:$B$9) -> 1 | S20: =ROUND(Q20*F20*R20,2) -> 210 | T20: =IF(M20="Paid",S20-J20,"") | U20: =IF(M20<>"Paid","",IF(T20>S20*0.05,"Underpaid","OK")) | V20: =_xlfn.XLOOKUP(C20,Payers!$A$2:$A$9,Payers!$B$2:$B$9) -> Self-Pay | W20: =TEXT(G20,"yyyy-mm") -> 2026-07
A21: CLM100022 | B21: PT11653 | C21: P08 | D21: C02 | E21: 99213 | F21: 1 | G21: 45972 | H21: 45973 | I21: 148.06 | J21: 148.06 | K21: 148.06 | L21: 0 | M21: Paid | O21: 46055 | P21: 46055 | Q21: =_xlfn.XLOOKUP(E21,CPT!$A$2:$A$13,CPT!$D$2:$D$13) -> 145 | R21: =_xlfn.XLOOKUP(C21,Contract!$A$2:$A$9,Contract!$B$2:$B$9) -> 1 | S21: =ROUND(Q21*F21*R21,2) -> 145 | T21: =IF(M21="Paid",S21-J21,"") -> -3.06 | U21: =IF(M21<>"Paid","",IF(T21>S21*0.05,"Underpaid","OK")) -> OK | V21: =_xlfn.XLOOKUP(C21,Payers!$A$2:$A$9,Payers!$B$2:$B$9) -> Self-Pay | W21: =TEXT(G21,"yyyy-mm") -> 2025-11
A22: CLM100023 | B22: PT10977 | C22: P02 | D22: C01 | E22: 20610 | F22: 1 | G22: 46235 | H22: 46236 | I22: 233.37 | J22: 101.79 | K22: 91.61 | L22: 10.18 | M22: Paid | O22: 46264 | P22: 46264 | Q22: =_xlfn.XLOOKUP(E22,CPT!$A$2:$A$13,CPT!$D$2:$D$13) -> 240 | R22: =_xlfn.XLOOKUP(C22,Contract!$A$2:$A$9,Contract!$B$2:$B$9) -> 0.43 | S22: =ROUND(Q22*F22*R22,2) -> 103.2 | T22: =IF(M22="Paid",S22-J22,"") -> 1.41 | U22: =IF(M22<>"Paid","",IF(T22>S22*0.05,"Underpaid","OK")) -> OK | V22: =_xlfn.XLOOKUP(C22,Payers!$A$2:$A$9,Payers!$B$2:$B$9) -> Summit Health Commercial | W22: =TEXT(G22,"yyyy-mm") -> 2026-08
A23: CLM100024 | B23: PT10300 | C23: P05 | D23: C01 | E23: 99214 | F23: 1 | G23: 46084 | H23: 46095 | I23: 209.46 | J23: 67.89 | K23: 67.89 | L23: 0 | M23: Paid | O23: 46158 | P23: 46158 | Q23: =_xlfn.XLOOKUP(E23,CPT!$A$2:$A$13,CPT!$D$2:$D$13) -> 210 | R23: =_xlfn.XLOOKUP(C23,Contract!$A$2:$A$9,Contract!$B$2:$B$9) -> 0.38 | S23: =ROUND(Q23*F23*R23,2) -> 79.8 | T23: =IF(M23="Paid",S23-J23,"") -> 11.91 | U23: =IF(M23<>"Paid","",IF(T23>S23*0.05,"Underpaid","OK")) -> Underpaid | V23: =_xlfn.XLOOKUP(C23,Payers!$A$2:$A$9,Payers!$B$2:$B$9) -> Sunshine Medicare Advantage | W23: =TEXT(G23,"yyyy-mm") -> 2026-03
A24: CLM100025 | B24: PT12735 | C24: P01 | D24: C02 | E24: 99204 | F24: 1 | G24: 46109 | H24: 46118 | I24: 265.94 | J24: 106.93 | K24: 106.93 | L24: 0 | M24: Paid | O24: 46152 | P24: 46152 | Q24: =_xlfn.XLOOKUP(E24,CPT!$A$2:$A$13,CPT!$D$2:$D$13) -> 260 | R24: =_xlfn.XLOOKUP(C24,Contract!$A$2:$A$9,Contract!$B$2:$B$9) -> 0.45 | S24: =ROUND(Q24*F24*R24,2) -> 117 | T24: =IF(M24="Paid",S24-J24,"") -> 10.07 | U24: =IF(M24<>"Paid","",IF(T24>S24*0.05,"Underpaid","OK")) -> Underpaid | V24: =_xlfn.XLOOKUP(C24,Payers!$A$2:$A$9,Payers!$B$2:$B$9) -> Blue Horizon Commercial | W24: =TEXT(G24,"yyyy-mm") -> 2026-03
A25: CLM100026 | B25: PT11404 | C25: P07 | D25: C04 | E25: 97140 | F25: 1 | G25: 45984 | H25: 45993 | I25: 57.18 | M25: Denied | N25: CO-16 | O25: 46029 | Q25: =_xlfn.XLOOKUP(E25,CPT!$A$2:$A$13,CPT!$D$2:$D$13) -> 58 | R25: =_xlfn.XLOOKUP(C25,Contract!$A$2:$A$9,Contract!$B$2:$B$9) -> 0.28 | S25: =ROUND(Q25*F25*R25,2) -> 16.24 | T25: =IF(M25="Paid",S25-J25,"") | U25: =IF(M25<>"Paid","",IF(T25>S25*0.05,"Underpaid","OK")) | V25: =_xlfn.XLOOKUP(C25,Payers!$A$2:$A$9,Payers!$B$2:$B$9) -> Coastal Medicaid MCO | W25: =TEXT(G25,"yyyy-mm") -> 2025-11
A26: CLM100027 | B26: PT10458 | C26: P04 | D26: C04 | E26: 97110 | F26: 1 | G26: 46072 | H26: 46078 | I26: 60.15 | J26: 23.28 | K26: 23.28 | L26: 0 | M26: Paid | O26: 46090 | P26: 46090 | Q26: =_xlfn.XLOOKUP(E26,CPT!$A$2:$A$13,CPT!$D$2:$D$13) -> 62 | R26: =_xlfn.XLOOKUP(C26,Contract!$A$2:$A$9,Contract!$B$2:$B$9) -> 0.36 | S26: =ROUND(Q26*F26*R26,2) -> 22.32 | T26: =IF(M26="Paid",S26-J26,"") -> -0.96 | U26: =IF(M26<>"Paid","",IF(T26>S26*0.05,"Underpaid","OK")) -> OK | V26: =_xlfn.XLOOKUP(C26,Payers!$A$2:$A$9,Payers!$B$2:$B$9) -> Medicare Part B | W26: =TEXT(G26,"yyyy-mm") -> 2026-02
A27: CLM100028 | B27: PT11262 | C27: P07 | D27: C01 | E27: J0702 | F27: 1 | G27: 46210 | H27: 46212 | I27: 36.94 | J27: 10.08 | K27: 10.08 | L27: 0 | M27: Paid | O27: 46266 | P27: 46266 | Q27: =_xlfn.XLOOKUP(E27,CPT!$A$2:$A$13,CPT!$D$2:$D$13) -> 38 | R27: =_xlfn.XLOOKUP(C27,Contract!$A$2:$A$9,Contract!$B$2:$B$9) -> 0.28 | S27: =ROUND(Q27*F27*R27,2) -> 10.64 | T27: =IF(M27="Paid",S27-J27,"") -> 0.56 | U27: =IF(M27<>"Paid","",IF(T27>S27*0.05,"Underpaid","OK")) -> Underpaid | V27: =_xlfn.XLOOKUP(C27,Payers!$A$2:$A$9,Payers!$B$2:$B$9) -> Coastal Medicaid MCO | W27: =TEXT(G27,"yyyy-mm") -> 2026-07
A28: CLM100029 | B28: PT10969 | C28: P07 | D28: C02 | E28: 99213 | F28: 1 | G28: 46038 | H28: 46043 | I28: 146.58 | M28: Denied | N28: CO-4 | O28: 46134 | Q28: =_xlfn.XLOOKUP(E28,CPT!$A$2:$A$13,CPT!$D$2:$D$13) -> 145 | R28: =_xlfn.XLOOKUP(C28,Contract!$A$2:$A$9,Contract!$B$2:$B$9) -> 0.28 | S28: =ROUND(Q28*F28*R28,2) -> 40.6 | T28: =IF(M28="Paid",S28-J28,"") | U28: =IF(M28<>"Paid","",IF(T28>S28*0.05,"Underpaid","OK")) | V28: =_xlfn.XLOOKUP(C28,Payers!$A$2:$A$9,Payers!$B$2:$B$9) -> Coastal Medicaid MCO | W28: =TEXT(G28,"yyyy-mm") -> 2026-01
A29: CLM100030 | B29: PT11092 | C29: P07 | D29: C04 | E29: 97110 | F29: 1 | G29: 45943 | H29: 45945 | I29: 62.88 | J29: 19.53 | K29: 19.53 | L29: 0 | M29: Paid | O29: 46001 | P29: 46001 | Q29: =_xlfn.XLOOKUP(E29,CPT!$A$2:$A$13,CPT!$D$2:$D$13) -> 62 | R29: =_xlfn.XLOOKUP(C29,Contract!$A$2:$A$9,Contract!$B$2:$B$9) -> 0.28 | S29: =ROUND(Q29*F29*R29,2) -> 17.36 | T29: =IF(M29="Paid",S29-J29,"") -> -2.17 | U29: =IF(M29<>"Paid","",IF(T29>S29*0.05,"Underpaid","OK")) -> OK | V29: =_xlfn.XLOOKUP(C29,Payers!$A$2:$A$9,Payers!$B$2:$B$9) -> Coastal Medicaid MCO | W29: =TEXT(G29,"yyyy-mm") -> 2025-10
A30: CLM100031 | B30: PT10913 | C30: P01 | D30: C01 | E30: J0702 | F30: 1 | G30: 45950 | H30: 45952 | I30: 38.82 | J30: 17.25 | K30: 17.25 | L30: 0 | M30: Paid | O30: 45974 | P30: 45974 | Q30: =_xlfn.XLOOKUP(E30,CPT!$A$2:$A$13,CPT!$D$2:$D$13) -> 38 | R30: =_xlfn.XLOOKUP(C30,Contract!$A$2:$A$9,Contract!$B$2:$B$9) -> 0.45 | S30: =ROUND(Q30*F30*R30,2) -> 17.1 | T30: =IF(M30="Paid",S30-J30,"") -> -0.15 | U30: =IF(M30<>"Paid","",IF(T30>S30*0.05,"Underpaid","OK")) -> OK | V30: =_xlfn.XLOOKUP(C30,Payers!$A$2:$A$9,Payers!$B$2:$B$9) -> Blue Horizon Commercial | W30: =TEXT(G30,"yyyy-mm") -> 2025-10
A31: CLM100032 | B31: PT12783 | C31: P02 | D31: C01 | E31: 99214 | F31: 1 | G31: 46073 | H31: 46087 | I31: 214.59 | J31: 95.78 | K31: 76.62 | L31: 19.16 | M31: Paid | O31: 46135 | P31: 46135 | Q31: =_xlfn.XLOOKUP(E31,CPT!$A$2:$A$13,CPT!$D$2:$D$13) -> 210 | R31: =_xlfn.XLOOKUP(C31,Contract!$A$2:$A$9,Contract!$B$2:$B$9) -> 0.43 | S31: =ROUND(Q31*F31*R31,2) -> 90.3 | T31: =IF(M31="Paid",S31-J31,"") -> -5.48 | U31: =IF(M31<>"Paid","",IF(T31>S31*0.05,"Underpaid","OK")) -> OK | V31: =_xlfn.XLOOKUP(C31,Payers!$A$2:$A$9,Payers!$B$2:$B$9) -> Summit Health Commercial | W31: =TEXT(G31,"yyyy-mm") -> 2026-02
A32: CLM100033 | B32: PT11787 | C32: P02 | D32: C04 | E32: 99213 | F32: 1 | G32: 45945 | H32: 45960 | I32: 141.65 | J32: 56.14 | K32: 50.53 | L32: 5.61 | M32: Paid | O32: 45999 | P32: 45999 | Q32: =_xlfn.XLOOKUP(E32,CPT!$A$2:$A$13,CPT!$D$2:$D$13) -> 145 | R32: =_xlfn.XLOOKUP(C32,Contract!$A$2:$A$9,Contract!$B$2:$B$9) -> 0.43 | S32: =ROUND(Q32*F32*R32,2) -> 62.35 | T32: =IF(M32="Paid",S32-J32,"") -> 6.21 | U32: =IF(M32<>"Paid","",IF(T32>S32*0.05,"Underpaid","OK")) -> Underpaid | V32: =_xlfn.XLOOKUP(C32,Payers!$A$2:$A$9,Payers!$B$2:$B$9) -> Summit Health Commercial | W32: =TEXT(G32,"yyyy-mm") -> 2025-10
A33: CLM100034 | B33: PT11491 | C33: P02 | D33: C02 | E33: 99213 | F33: 1 | G33: 46226 | H33: 46227 | I33: 142.3 | J33: 61.21 | K33: 61.21 | L33: 0 | M33: Paid | O33: 46265 | P33: 46265 | Q33: =_xlfn.XLOOKUP(E33,CPT!$A$2:$A$13,CPT!$D$2:$D$13) -> 145 | R33: =_xlfn.XLOOKUP(C33,Contract!$A$2:$A$9,Contract!$B$2:$B$9) -> 0.43 | S33: =ROUND(Q33*F33*R33,2) -> 62.35 | T33: =IF(M33="Paid",S33-J33,"") -> 1.14 | U33: =IF(M33<>"Paid","",IF(T33>S33*0.05,"Underpaid","OK")) -> OK | V33: =_xlfn.XLOOKUP(C33,Payers!$A$2:$A$9,Payers!$B$2:$B$9) -> Summit Health Commercial | W33: =TEXT(G33,"yyyy-mm") -> 2026-07
A34: CLM100035 | B34: PT12270 | C34: P04 | D34: C02 | E34: 99204 | F34: 1 | G34: 46270 | H34: 46276 | I34: 265.43 | J34: 89.89 | K34: 80.9 | L34: 8.99 | M34: Paid | O34: 46289 | P34: 46289 | Q34: =_xlfn.XLOOKUP(E34,CPT!$A$2:$A$13,CPT!$D$2:$D$13) -> 260 | R34: =_xlfn.XLOOKUP(C34,Contract!$A$2:$A$9,Contract!$B$2:$B$9) -> 0.36 | S34: =ROUND(Q34*F34*R34,2) -> 93.6 | T34: =IF(M34="Paid",S34-J34,"") -> 3.71 | U34: =IF(M34<>"Paid","",IF(T34>S34*0.05,"Underpaid","OK")) -> OK | V34: =_xlfn.XLOOKUP(C34,Payers!$A$2:$A$9,Payers!$B$2:$B$9) -> Medicare Part B | W34: =TEXT(G34,"yyyy-mm") -> 2026-09
A35: CLM100036 | B35: PT11244 | C35: P04 | D35: C01 | E35: 73721 | F35: 1 | G35: 46125 | H35: 46135 | I35: 1061.17 | J35: 358.36 | K35: 358.36 | L35: 0 | M35: Paid | O35: 46155 | P35: 46155 | Q35: =_xlfn.XLOOKUP(E35,CPT!$A$2:$A$13,CPT!$D$2:$D$13) -> 1050 | R35: =_xlfn.XLOOKUP(C35,Contract!$A$2:$A$9,Contract!$B$2:$B$9) -> 0.36 | S35: =ROUND(Q35*F35*R35,2) -> 378 | T35: =IF(M35="Paid",S35-J35,"") -> 19.64 | U35: =IF(M35<>"Paid","",IF(T35>S35*0.05,"Underpaid","OK")) -> Underpaid | V35: =_xlfn.XLOOKUP(C35,Payers!$A$2:$A$9,Payers!$B$2:$B$9) -> Medicare Part B | W35: =TEXT(G35,"yyyy-mm") -> 2026-04
A36: CLM100037 | B36: PT12698 | C36: P06 | D36: C01 | E36: 73721 | F36: 1 | G36: 46241 | H36: 46244 | I36: 1059.75 | J36: 260.65 | K36: 260.65 | L36: 0 | M36: Paid | O36: 46258 | P36: 46258 | Q36: =_xlfn.XLOOKUP(E36,CPT!$A$2:$A$13,CPT!$D$2:$D$13) -> 1050 | R36: =_xlfn.XLOOKUP(C36,Contract!$A$2:$A$9,Contract!$B$2:$B$9) -> 0.27 | S36: =ROUND(Q36*F36*R36,2) -> 283.5 | T36: =IF(M36="Paid",S36-J36,"") -> 22.85 | U36: =IF(M36<>"Paid","",IF(T36>S36*0.05,"Underpaid","OK")) -> Underpaid | V36: =_xlfn.XLOOKUP(C36,Payers!$A$2:$A$9,Payers!$B$2:$B$9) -> Florida Medicaid | W36: =TEXT(G36,"yyyy-mm") -> 2026-08
A37: CLM100038 | B37: PT13303 | C37: P04 | D37: C01 | E37: 20610 | F37: 1 | G37: 46248 | H37: 46255 | I37: 237.63 | J37: 90.15 | K37: 90.15 | L37: 0 | M37: Paid | O37: 46274 | P37: 46274 | Q37: =_xlfn.XLOOKUP(E37,CPT!$A$2:$A$13,CPT!$D$2:$D$13) -> 240 | R37: =_xlfn.XLOOKUP(C37,Contract!$A$2:$A$9,Contract!$B$2:$B$9) -> 0.36 | S37: =ROUND(Q37*F37*R37,2) -> 86.4 | T37: =IF(M37="Paid",S37-J37,"") -> -3.75 | U37: =IF(M37<>"Paid","",IF(T37>S37*0.05,"Underpaid","OK")) -> OK | V37: =_xlfn.XLOOKUP(C37,Payers!$A$2:$A$9,Payers!$B$2:$B$9) -> Medicare Part B | W37: =TEXT(G37,"yyyy-mm") -> 2026-08
A38: CLM100039 | B38: PT12024 | C38: P01 | D38: C01 | E38: 99204 | F38: 1 | G38: 46174 | H38: 46180 | I38: 261.74 | J38: 131.93 | K38: 105.54 | L38: 26.39 | M38: Paid | O38: 46196 | P38: 46196 | Q38: =_xlfn.XLOOKUP(E38,CPT!$A$2:$A$13,CPT!$D$2:$D$13) -> 260 | R38: =_xlfn.XLOOKUP(C38,Contract!$A$2:$A$9,Contract!$B$2:$B$9) -> 0.45 | S38: =ROUND(Q38*F38*R38,2) -> 117 | T38: =IF(M38="Paid",S38-J38,"") -> -14.93 | U38: =IF(M38<>"Paid","",IF(T38>S38*0.05,"Underpaid","OK")) -> OK | V38: =_xlfn.XLOOKUP(C38,Payers!$A$2:$A$9,Payers!$B$2:$B$9) -> Blue Horizon Commercial | W38: =TEXT(G38,"yyyy-mm") -> 2026-06
A39: CLM100040 | B39: PT10720 | C39: P04 | D39: C02 | E39: 99214 | F39: 1 | G39: 45933 | H39: 45941 | I39: 214.95 | J39: 84.08 | K39: 84.08 | L39: 0 | M39: Paid | O39: 45955 | P39: 45955 | Q39: =_xlfn.XLOOKUP(E39,CPT!$A$2:$A$13,CPT!$D$2:$D$13) -> 210 | R39: =_xlfn.XLOOKUP(C39,Contract!$A$2:$A$9,Contract!$B$2:$B$9) -> 0.36 | S39: =ROUND(Q39*F39*R39,2) -> 75.6 | T39: =IF(M39="Paid",S39-J39,"") -> -8.48 | U39: =IF(M39<>"Paid","",IF(T39>S39*0.05,"Underpaid","OK")) -> OK | V39: =_xlfn.XLOOKUP(C39,Payers!$A$2:$A$9,Payers!$B$2:$B$9) -> Medicare Part B | W39: =TEXT(G39,"yyyy-mm") -> 2025-10
A40: CLM100041 | B40: PT13093 | C40: P03 | D40: C04 | E40: 99213 | F40: 1 | G40: 45956 | H40: 45966 | I40: 145.5 | M40: Denied | N40: CO-27 | O40: 46000 | Q40: =_xlfn.XLOOKUP(E40,CPT!$A$2:$A$13,CPT!$D$2:$D$13) -> 145 | R40: =_xlfn.XLOOKUP(C40,Contract!$A$2:$A$9,Contract!$B$2:$B$9) -> 0.47 | S40: =ROUND(Q40*F40*R40,2) -> 68.15 | T40: =IF(M40="Paid",S40-J40,"") | U40: =IF(M40<>"Paid","",IF(T40>S40*0.05,"Underpaid","OK")) | V40: =_xlfn.XLOOKUP(C40,Payers!$A$2:$A$9,Payers!$B$2:$B$9) -> Keystone Commercial PPO | W40: =TEXT(G40,"yyyy-mm") -> 2025-10
...

Sheet Checks
A1: Check | B1: Result | C1: Expected | D1: Match?
A2: Claims rows | B2: =ROWS(tblClaims[]) -> 6094 | C2: 6094 | D2: =ROUND(B2,2)=ROUND(C2,2) -> TRUE
A3: Payers rows | B3: =ROWS(tblPayers[]) -> 8 | C3: 8 | D3: =ROUND(B3,2)=ROUND(C3,2) -> TRUE
A4: CPT rows | B4: =ROWS(tblCPT[]) -> 12 | C4: 12 | D4: =ROUND(B4,2)=ROUND(C4,2) -> TRUE
A5: Contract rows | B5: =ROWS(tblContract[]) -> 8 | C5: 8 | D5: =ROUND(B5,2)=ROUND(C5,2) -> TRUE
A6: Unique claim_id | B6: =COUNTA(_xlfn.UNIQUE(tblClaims[claim_id])) -> 6094 | C6: 6094 | D6: =ROUND(B6,2)=ROUND(C6,2) -> TRUE
A7: Paid claims | B7: =COUNTIFS(tblClaims[claim_status],"Paid") -> 4321 | C7: 4321 | D7: =ROUND(B7,2)=ROUND(C7,2) -> TRUE
A8: Denied claims | B8: =COUNTIFS(tblClaims[claim_status],"Denied") -> 1037 | C8: 1037 | D8: =ROUND(B8,2)=ROUND(C8,2) -> TRUE
A9: Pending claims | B9: =COUNTIFS(tblClaims[claim_status],"Pending") -> 736 | C9: 736 | D9: =ROUND(B9,2)=ROUND(C9,2) -> TRUE
A10: Blank paid_amount | B10: =COUNTBLANK(tblClaims[paid_amount]) -> 1773 | C10: 1773 | D10: =ROUND(B10,2)=ROUND(C10,2) -> TRUE
A11: Total billed | B11: =SUM(tblClaims[billed_amount]) -> 10945471 | C11: 10945471 | D11: =ROUND(B11,2)=ROUND(C11,2) -> TRUE
A12: Total allowed | B12: =SUM(tblClaims[allowed_amount]) -> 2966855.9 | C12: 2966855.9 | D12: =ROUND(B12,2)=ROUND(C12,2) -> TRUE
A13: Total paid | B13: =SUM(tblClaims[paid_amount]) -> 2722001.7 | C13: =SUM(tblClaims[paid_amount]) -> 2722001.7 | D13: =ROUND(B13,2)=ROUND(C13,2) -> TRUE
A14: Total expected | B14: =SUM(Claims!S:S) -> 4454871.4 | C14: 4454871.4 | D14: =ROUND(B14,2)=ROUND(C14,2) -> TRUE
A15: Total variance | B15: =SUM(Claims!T:T) -> 1396.86 | C15: 1396.86 | D15: =ROUND(B15,2)=ROUND(C15,2) -> TRUE
A16: underpaid count | B16: =COUNTIF(Claims!U:U,"Underpaid") -> 1459 | C16: 1459 | D16: =ROUND(B16,2)=ROUND(C16,2) -> TRUE
A17: Underpaid $ | B17: =SUMIF(Claims!U:U,"Underpaid",Claims!T:T) -> 107894.87 | C17: 107894.87 | D17: =ROUND(B17,2)=ROUND(C17,2) -> TRUE
